[2021-01-05 15:50:48,147][Thread-1:10332][task_id:django.request][exception.py:135][ERROR][Internal Server Error: /]
Traceback (most recent call last):
  File "C:\Python27\lib\site-packages\django\core\handlers\exception.py", line 41, in inner
    response = get_response(request)
  File "C:\Python27\lib\site-packages\django\core\handlers\base.py", line 187, in _get_response
    response = self.process_exception_by_middleware(e, request)
  File "C:\Python27\lib\site-packages\django\core\handlers\base.py", line 185, in _get_response
    response = wrapped_callback(request, *callback_args, **callback_kwargs)
  File "C:\Python27\lib\site-packages\django\contrib\auth\decorators.py", line 23, in _wrapped_view
    return view_func(request, *args, **kwargs)
  File "D:\PycharmProjects\cmdb\cmdb\views.py", line 13, in index
    return render(request, 'index.html')
  File "C:\Python27\lib\site-packages\django\shortcuts.py", line 30, in render
    content = loader.render_to_string(template_name, context, request, using=using)
  File "C:\Python27\lib\site-packages\django\template\loader.py", line 67, in render_to_string
    template = get_template(template_name, using=using)
  File "C:\Python27\lib\site-packages\django\template\loader.py", line 21, in get_template
    return engine.get_template(template_name)
  File "C:\Python27\lib\site-packages\django\template\backends\django.py", line 39, in get_template
    return Template(self.engine.get_template(template_name), self)
  File "C:\Python27\lib\site-packages\django\template\engine.py", line 162, in get_template
    template, origin = self.find_template(template_name)
  File "C:\Python27\lib\site-packages\django\template\engine.py", line 136, in find_template
    name, template_dirs=dirs, skip=skip,
  File "C:\Python27\lib\site-packages\django\template\loaders\base.py", line 44, in get_template
    contents, origin, origin.template_name, self.engine,
  File "C:\Python27\lib\site-packages\django\template\base.py", line 191, in __init__
    self.nodelist = self.compile_nodelist()
  File "C:\Python27\lib\site-packages\django\template\base.py", line 230, in compile_nodelist
    return parser.parse()
  File "C:\Python27\lib\site-packages\django\template\base.py", line 515, in parse
    raise self.error(token, e)
TemplateSyntaxError: 'extends' cannot appear more than once in the same template
[2021-01-07 19:06:51,907][Thread-1089:12764][task_id:django.request][exception.py:135][ERROR][Internal Server Error: /accounts/login/]
Traceback (most recent call last):
  File "C:\Python27\lib\site-packages\django\core\handlers\exception.py", line 41, in inner
    response = get_response(request)
  File "C:\Python27\lib\site-packages\django\core\handlers\base.py", line 198, in _get_response
    "returned None instead." % (callback.__module__, view_name)
ValueError: The view apps.accounts.views.Account_Login didn't return an HttpResponse object. It returned None instead.
[2021-01-07 19:07:12,619][Thread-1090:17456][task_id:django.request][exception.py:135][ERROR][Internal Server Error: /accounts/login/]
Traceback (most recent call last):
  File "C:\Python27\lib\site-packages\django\core\handlers\exception.py", line 41, in inner
    response = get_response(request)
  File "C:\Python27\lib\site-packages\django\core\handlers\base.py", line 198, in _get_response
    "returned None instead." % (callback.__module__, view_name)
ValueError: The view apps.accounts.views.Account_Login didn't return an HttpResponse object. It returned None instead.
[2021-01-07 19:07:18,023][Thread-1094:12036][task_id:django.request][exception.py:135][ERROR][Internal Server Error: /accounts/login/]
Traceback (most recent call last):
  File "C:\Python27\lib\site-packages\django\core\handlers\exception.py", line 41, in inner
    response = get_response(request)
  File "C:\Python27\lib\site-packages\django\core\handlers\base.py", line 198, in _get_response
    "returned None instead." % (callback.__module__, view_name)
ValueError: The view apps.accounts.views.Account_Login didn't return an HttpResponse object. It returned None instead.
[2021-01-07 19:08:04,648][Thread-1096:24476][task_id:django.request][exception.py:135][ERROR][Internal Server Error: /accounts/login/]
Traceback (most recent call last):
  File "C:\Python27\lib\site-packages\django\core\handlers\exception.py", line 41, in inner
    response = get_response(request)
  File "C:\Python27\lib\site-packages\django\core\handlers\base.py", line 198, in _get_response
    "returned None instead." % (callback.__module__, view_name)
ValueError: The view apps.accounts.views.Account_Login didn't return an HttpResponse object. It returned None instead.
[2021-01-07 19:08:39,736][Thread-1100:15760][task_id:django.request][exception.py:135][ERROR][Internal Server Error: /accounts/login/]
Traceback (most recent call last):
  File "C:\Python27\lib\site-packages\django\core\handlers\exception.py", line 41, in inner
    response = get_response(request)
  File "C:\Python27\lib\site-packages\django\core\handlers\base.py", line 198, in _get_response
    "returned None instead." % (callback.__module__, view_name)
ValueError: The view apps.accounts.views.Account_Login didn't return an HttpResponse object. It returned None instead.
[2021-01-07 19:09:56,273][Thread-1103:9152][task_id:django.request][exception.py:135][ERROR][Internal Server Error: /accounts/login/]
Traceback (most recent call last):
  File "C:\Python27\lib\site-packages\django\core\handlers\exception.py", line 41, in inner
    response = get_response(request)
  File "C:\Python27\lib\site-packages\django\core\handlers\base.py", line 198, in _get_response
    "returned None instead." % (callback.__module__, view_name)
ValueError: The view apps.accounts.views.Account_Login didn't return an HttpResponse object. It returned None instead.
[2021-01-07 19:10:25,759][Thread-1104:13140][task_id:django.request][exception.py:135][ERROR][Internal Server Error: /accounts/login/]
Traceback (most recent call last):
  File "C:\Python27\lib\site-packages\django\core\handlers\exception.py", line 41, in inner
    response = get_response(request)
  File "C:\Python27\lib\site-packages\django\core\handlers\base.py", line 198, in _get_response
    "returned None instead." % (callback.__module__, view_name)
ValueError: The view apps.accounts.views.Account_Login didn't return an HttpResponse object. It returned None instead.
[2021-01-07 20:16:55,355][Thread-6:14744][task_id:django.request][exception.py:135][ERROR][Internal Server Error: /accounts/register/]
Traceback (most recent call last):
  File "C:\Python27\lib\site-packages\django\core\handlers\exception.py", line 41, in inner
    response = get_response(request)
  File "C:\Python27\lib\site-packages\django\core\handlers\base.py", line 187, in _get_response
    response = self.process_exception_by_middleware(e, request)
  File "C:\Python27\lib\site-packages\django\core\handlers\base.py", line 185, in _get_response
    response = wrapped_callback(request, *callback_args, **callback_kwargs)
  File "D:\PycharmProjects\cmdb\apps\accounts\views.py", line 25, in Account_Register
    User.objects.create_user(username=username, password=password)
  File "C:\Python27\lib\site-packages\django\contrib\auth\models.py", line 159, in create_user
    return self._create_user(username, email, password, **extra_fields)
  File "C:\Python27\lib\site-packages\django\contrib\auth\models.py", line 153, in _create_user
    user.save(using=self._db)
  File "C:\Python27\lib\site-packages\django\contrib\auth\base_user.py", line 80, in save
    super(AbstractBaseUser, self).save(*args, **kwargs)
  File "C:\Python27\lib\site-packages\django\db\models\base.py", line 808, in save
    force_update=force_update, update_fields=update_fields)
  File "C:\Python27\lib\site-packages\django\db\models\base.py", line 838, in save_base
    updated = self._save_table(raw, cls, force_insert, force_update, using, update_fields)
  File "C:\Python27\lib\site-packages\django\db\models\base.py", line 924, in _save_table
    result = self._do_insert(cls._base_manager, using, fields, update_pk, raw)
  File "C:\Python27\lib\site-packages\django\db\models\base.py", line 963, in _do_insert
    using=using, raw=raw)
  File "C:\Python27\lib\site-packages\django\db\models\manager.py", line 85, in manager_method
    return getattr(self.get_queryset(), name)(*args, **kwargs)
  File "C:\Python27\lib\site-packages\django\db\models\query.py", line 1079, in _insert
    return query.get_compiler(using=using).execute_sql(return_id)
  File "C:\Python27\lib\site-packages\django\db\models\sql\compiler.py", line 1112, in execute_sql
    cursor.execute(sql, params)
  File "C:\Python27\lib\site-packages\django\db\backends\utils.py", line 79, in execute
    return super(CursorDebugWrapper, self).execute(sql, params)
  File "C:\Python27\lib\site-packages\django\db\backends\utils.py", line 64, in execute
    return self.cursor.execute(sql, params)
  File "C:\Python27\lib\site-packages\django\db\utils.py", line 94, in __exit__
    six.reraise(dj_exc_type, dj_exc_value, traceback)
  File "C:\Python27\lib\site-packages\django\db\backends\utils.py", line 64, in execute
    return self.cursor.execute(sql, params)
  File "C:\Python27\lib\site-packages\django\db\backends\sqlite3\base.py", line 328, in execute
    return Database.Cursor.execute(self, query, params)
IntegrityError: column username is not unique
[2021-01-07 20:34:59,226][Thread-35:12720][task_id:django.request][exception.py:135][ERROR][Internal Server Error: /accounts/set_password/]
Traceback (most recent call last):
  File "C:\Python27\lib\site-packages\django\core\handlers\exception.py", line 41, in inner
    response = get_response(request)
  File "C:\Python27\lib\site-packages\django\core\handlers\base.py", line 198, in _get_response
    "returned None instead." % (callback.__module__, view_name)
ValueError: The view apps.accounts.views.Account_Set_password didn't return an HttpResponse object. It returned None instead.
